{\rtf1\ansi\ansicpg1252\cocoartf2708
\cocoatextscaling0\cocoaplatform0{\fonttbl\f0\fmodern\fcharset0 Courier;}
{\colortbl;\red255\green255\blue255;\red0\green0\blue0;\red255\green255\blue255;}
{\*\expandedcolortbl;;\cssrgb\c0\c0\c0;\cssrgb\c100000\c100000\c100000;}
\paperw11900\paperh16840\margl1440\margr1440\vieww29740\viewh16300\viewkind0
\pard\tx560\tx1120\tx1680\tx2240\tx2800\tx3360\tx3920\tx4480\tx5040\tx5600\tx6160\tx6720\pardirnatural\partightenfactor0

\f0\fs24 \cf2 \cb3 \CocoaLigature0 [2023-02-13 10:14:03,351: INFO/MainProcess] Task instabase.registry.tasks.sdlc_operation[441543dd-d862-432b-806a-ed525a6f2707] received\
[2023-02-13 10:14:03,354: INFO/MainProcess] Task instabase.registry.tasks.core_echo[afbaa941-a0c6-4128-9580-97d36f22ec9d] received\
[2023-02-13 10:14:03,368: INFO/MainProcess] Task instabase.registry.tasks.core_echo[afbaa941-a0c6-4128-9580-97d36f22ec9d] succeeded in 0.010703432373702526s: \{'status': 'OK', 'ignore': True\}\
[2023-02-13 10:14:03,447: WARNING/MainProcess] Loading ignore failed - there seems to be no .ignore file\
[2023-02-13 10:14:08,267: ERROR/MainProcess] too many redirects or authentication replays\
Traceback (most recent call last):\
  File "/instabase-server/py/instabase/registry/tasks.py", line 284, in sdlc_operation\
    username).to_dict()\
  File "/instabase-server/py/instabase/tasks/sdlc/sdlc_manager.py", line 45, in handle_sdlc_request\
    response = project.push_version(message)\
  File "/instabase-server/py/instabase/tasks/sdlc/sdlc_project.py", line 86, in push_version\
    self.config.target_branch, message, diff, file_contents)\
  File "/instabase-server/py/instabase/tasks/sdlc/git_repos/pygit_provider.py", line 226, in create_remote_commit\
    remote.push(['refs/heads/\{\}'.format(branch)], callbacks=self.callbacks)\
  File "/home/ibuser/.local/lib/python3.7/site-packages/pygit2/remote.py", line 224, in push\
    payload.check_error(err)\
  File "/home/ibuser/.local/lib/python3.7/site-packages/pygit2/callbacks.py", line 93, in check_error\
    check_error(error_code)\
  File "/home/ibuser/.local/lib/python3.7/site-packages/pygit2/errors.py", line 65, in check_error\
    raise GitError(message)\
_pygit2.GitError: too many redirects or authentication replays\
[2023-02-13 10:14:08,276: INFO/MainProcess] Task instabase.registry.tasks.sdlc_operation[441543dd-d862-432b-806a-ed525a6f2707] succeeded in 4.923581789014861s: \{'status': 'ERROR', 'msg': 'Unable to push version'\}}